Traceback (most recent call last):
  File "/home/ibpad-005023/Documentos/Observatorio-google/roda_pesquisas.py", line 93, in <module>
    main()
  File "/home/ibpad-005023/Documentos/Observatorio-google/roda_pesquisas.py", line 81, in main
    gmail_sign_in(driver, profile)
  File "/home/ibpad-005023/Documentos/Observatorio-google/roda_pesquisas.py", line 32, in gmail_sign_in
    driver.get("http://mail.google.com")
  File "/home/ibpad-005023/Documentos/Observatorio-google/venv/lib/python3.6/site-packages/selenium/webdriver/remote/webdriver.py", line 326, in get
    self.execute(Command.GET, {'url': url})
  File "/home/ibpad-005023/Documentos/Observatorio-google/venv/lib/python3.6/site-packages/selenium/webdriver/remote/webdriver.py", line 314, in execute
    self.error_handler.check_response(response)
  File "/home/ibpad-005023/Documentos/Observatorio-google/venv/lib/python3.6/site-packages/selenium/webdriver/remote/errorhandler.py", line 242, in check_response
    raise exception_class(message, screen, stacktrace)
selenium.common.exceptions.WebDriverException: Message: Reached error page: about:neterror?e=dnsNotFound&u=http%3A//mail.google.com/&c=UTF-8&f=regular&d=N%C3%A3o%20conseguimos%20conectar%20com%20o%20servidor%20em%20mail.google.com.

