Traceback (most recent call last):
  File "/home/ibpad-005023/Documentos/Observatorio-google/roda_pesquisas.py", line 93, in <module>
    main()
  File "/home/ibpad-005023/Documentos/Observatorio-google/roda_pesquisas.py", line 78, in main
    driver = webdriver.Firefox(fireforx_profile, firefox_options=options)
  File "/home/ibpad-005023/Documentos/Observatorio-google/venv/lib/python3.6/site-packages/selenium/webdriver/firefox/webdriver.py", line 170, in __init__
    keep_alive=True)
  File "/home/ibpad-005023/Documentos/Observatorio-google/venv/lib/python3.6/site-packages/selenium/webdriver/remote/webdriver.py", line 156, in __init__
    self.start_session(capabilities, browser_profile)
  File "/home/ibpad-005023/Documentos/Observatorio-google/venv/lib/python3.6/site-packages/selenium/webdriver/remote/webdriver.py", line 245, in start_session
    response = self.execute(Command.NEW_SESSION, parameters)
  File "/home/ibpad-005023/Documentos/Observatorio-google/venv/lib/python3.6/site-packages/selenium/webdriver/remote/webdriver.py", line 314, in execute
    self.error_handler.check_response(response)
  File "/home/ibpad-005023/Documentos/Observatorio-google/venv/lib/python3.6/site-packages/selenium/webdriver/remote/errorhandler.py", line 242, in check_response
    raise exception_class(message, screen, stacktrace)
selenium.common.exceptions.WebDriverException: Message: connection refused

